Workbook

Sheet Cover
C1: INFOSYS LIMITED - Financial Analysis & Valuation Report
C2: FY 2020 – FY 2024 | All figures in ₹ Crores
B4: Prepared by: | C4: Ashley Brian R
B5: Subject: | C5: Financial Statement Analysis, Forecasting and Valuation of a Company
B6: Date: | C6: May 2026
B8: Sections | C8: TABLE OF CONTENTS
C9: Raw Data | D9: Given historical IS & BS data + assumptions
B10: 1 | C10: Accounting Concepts | D10: Que 1–3: Concepts, cycle, 3-statement relationship
C11: Income Statement | D11: Que 4–5: Common size & comparative analysis
B12: 2 | C12: Financial Ratios | D12: Que 6: Liquidity, profitability, leverage ratios
C13: Trend Analysis | D13: Que 7: Revenue & profit trends with interpretation
B14: 3 | C14: 3-Statement Model | D14: Que 8–9: Integrated IS / BS / CFS model
B15: 4 | C15: Forecasting | D15: Que 10–11: 5-year revenue, profit & FCF forecast
B16: 5 | C16: DCF Valuation | D16: Que 12–18: WACC, FCF, terminal value, equity value
B17: 6 | C17: Other Valuations | D17: Que 19–20: Book value, Adjusted book value per share
B18: 7 | C18: EBITDA & EV | D18: Que 21: Calculating EBITDA & EV
B19: 8 | C19: Relative Valuation | D19: Que 22: EV/EBITDA & P/E Method
B20: 9 | C20: Replacement Cost Model | D20: Que 23–24: RCM
B21: 10 | C21: Beta Analysis | D21: Que 25–26: Asset beta, Equity beta, Unlevered & Re-levered
B22: 11 | C22: Startup Valuation | D22: Que 27 : Explain startup
B23: 12 | C23: Sensitivity Analysis | D23: Que 28: WACC × growth rate matrix
B24: 13 | C24: Charts | D24: Que 29: Revenue, profit, margin charts
B25: 14 | C25: Final Conclusion | D25: Que 30: Valuation verdict

Sheet Raw Data
A1: RAW DATA - Infosys Limited (₹ Crores)
A2: INCOME STATEMENT (Given inputs from question)
B3: FY 2020 | C3: FY 2021 | D3: FY 2022 | E3: FY 2023 | F3: FY 2024
A4: Revenue | B4: 90000 | C4: 95000 | D4: 100000 | E4: 110000 | F4: 120000
A5: Operating Expenses | B5: 65000 | C5: 68000 | D5: 70000 | E5: 75000 | F5: 82000
A6: Depreciation | B6: 4000 | C6: 4200 | D6: 4500 | E6: 4800 | F6: 5000
A7: Interest Expense | B7: 500 | C7: 500 | D7: 600 | E7: 650 | F7: 700
A8: Tax Rate | B8: 0.25 | C8: 0.25 | D8: 0.25 | E8: 0.25 | F8: 0.25
A9: DERIVED FIGURES
B10: FY 2020 | C10: FY 2021 | D10: FY 2022 | E10: FY 2023 | F10: FY 2024
A11: EBIT | B11: =B4-B5-B6 -> 21000 | C11: =C4-C5-C6 -> 22800 | D11: =D4-D5-D6 -> 25500 | E11: =E4-E5-E6 -> 30200 | F11: =F4-F5-F6 -> 33000
A12: EBITDA | B12: =B11+B6 -> 25000 | C12: =C11+C6 -> 27000 | D12: =D11+D6 -> 30000 | E12: =E11+E6 -> 35000 | F12: =F11+F6 -> 38000
A13: EBT | B13: =B11-B7 -> 20500 | C13: =C11-C7 -> 22300 | D13: =D11-D7 -> 24900 | E13: =E11-E7 -> 29550 | F13: =F11-F7 -> 32300
A14: Tax | B14: =B13*B8 -> 5125 | C14: =C13*C8 -> 5575 | D14: =D13*D8 -> 6225 | E14: =E13*E8 -> 7387.5 | F14: =F13*F8 -> 8075
A15: Net Profit | B15: =B13-B14 -> 15375 | C15: =C13-C14 -> 16725 | D15: =D13-D14 -> 18675 | E15: =E13-E14 -> 22162.5 | F15: =F13-F14 -> 24225
A17: BALANCE SHEET
B18: FY 2020 | C18: FY 2021 | D18: FY 2022 | E18: FY 2023 | F18: FY 2024
A19: Total Assets | B19: 120000 | C19: 130000 | D19: 140000 | E19: 155000 | F19: 170000
A20: Total Debt | B20: 20000 | C20: 22000 | D20: 23000 | E20: 25000 | F20: 27000
A21: Cash & Equivalents | B21: 10000 | C21: 12000 | D21: 15000 | E21: 18000 | F21: 20000
A22: Total Equity | B22: 100000 | C22: 108000 | D22: 117000 | E22: 130000 | F22: 143000
A24: KEY ASSUMPTIONS
A25: Assumption | B25: Value
A26: Risk-Free Rate (Rf) | B26: 0.06
A27: Market Return (Rm) | B27: 0.12
A28: Equity Beta (β) | B28: 1.1
A29: Cost of Debt (Kd) | B29: 0.08
A30: Shares Outstanding (Crores) | B30: 420
A31: Terminal Growth Rate (g) | B31: 0.05

Sheet Accounting Concepts
B1: SECTION 1 - ACCOUNTING CONCEPTS - Questions 1, 2 & 3
B3: Question 1: Basic Accounting Assumptions
B4: Concept | C4: Explanation
B5: Going Concern | C5: The going concern assumption presumes that a business will continue operating indefinitely into the foreseeable future without being forced to liquidate assets. Financial statements are prepared on this basis - assets are recorded at historical cost, not liquidation value. If violated (e.g., near bankruptcy), statements must be prepared on a break-up basis.
B6: Consistency | C6: The consistency principle requires that the same accounting methods are applied from one period to the next (e.g., same depreciation method). This enables meaningful year-on-year comparisons. Any change must be disclosed with its financial impact.
B7: Accrual Concept | C7: Revenues are recognised when earned (not when cash is received), and expenses are recorded when incurred (not when paid). Example: If Infosys completes a project in March but invoices in April, revenue is still recorded in March. This gives a more accurate picture than cash-basis accounting.
B9: Question 2: The Accounting Cycle
B10: Concept | C10: Explanation
B11: Journal | C11: The book of original entry. Every transaction is first recorded chronologically as a journal entry using double-entry (debit one account, credit another). E.g.: Revenue received → Debit Cash, Credit Revenue.
B12: Ledger | C12: The book of final entry. Journal entries are posted to individual ledger accounts to build up balances. E.g.: All cash transactions are posted to the Cash ledger account.
B13: Trial Balance | C13: A statement listing all ledger account balances at period-end to check arithmetical accuracy - total debits must equal total credits. It is a working paper, not a final statement.
B14: Final Accounts | C14: Comprise the Income Statement (profit/loss), Balance Sheet (financial position), and Cash Flow Statement (cash movements). Prepared from the adjusted trial balance - the formal output of the accounting cycle.
B16: Question 3: Relationship Between the Three Financial Statements
B17: Link | C17: Explanation
B18: IS → Balance Sheet | C18: Net Profit from the Income Statement flows into the Balance Sheet via Retained Earnings (within Equity). A profitable year increases equity.
B19: IS → Cash Flow Stmt | C19: Net Profit is the starting point for the indirect method Cash Flow Statement (Operating Question). Non-cash items like Depreciation are added back.
B20: BS → Cash Flow Stmt | C20: Changes in Balance Sheet working capital items (receivables, payables) appear as adjustments in Operating Cash Flows. Capex links to changes in fixed assets; debt issuances appear in Financing Cash Flows.
B21: CFS → Balance Sheet | C21: The closing cash balance in the Cash Flow Statement equals the Cash & Equivalents figure on the Balance Sheet.

Sheet Income Statement
A1: SECTION 2 - INCOME STATEMENT ANALYSIS (₹ Crores)
A2: Question 4: Common Size Income Statement (% of Revenue)
A3: Item | B3: FY 2020 | C3: FY 2021 | D3: FY 2022 | E3: FY 2023 | F3: FY 2024
A4: Revenue | B4: ='Raw Data'!B4/'Raw Data'!B4 -> 1 | C4: ='Raw Data'!C4/'Raw Data'!C4 -> 1 | D4: ='Raw Data'!D4/'Raw Data'!D4 -> 1 | E4: ='Raw Data'!E4/'Raw Data'!E4 -> 1 | F4: ='Raw Data'!F4/'Raw Data'!F4 -> 1
A5: (-) Operating Exp. | B5: ='Raw Data'!B5/'Raw Data'!B4 -> 0.72222222 | C5: ='Raw Data'!C5/'Raw Data'!C4 -> 0.71578947 | D5: ='Raw Data'!D5/'Raw Data'!D4 -> 0.7 | E5: ='Raw Data'!E5/'Raw Data'!E4 -> 0.68181818 | F5: ='Raw Data'!F5/'Raw Data'!F4 -> 0.68333333
A6: (-) Depreciation | B6: ='Raw Data'!B6/'Raw Data'!B4 -> 0.044444444 | C6: ='Raw Data'!C6/'Raw Data'!C4 -> 0.044210526 | D6: ='Raw Data'!D6/'Raw Data'!D4 -> 0.045 | E6: ='Raw Data'!E6/'Raw Data'!E4 -> 0.043636364 | F6: ='Raw Data'!F6/'Raw Data'!F4 -> 0.041666667
A7: EBIT | B7: ='Raw Data'!B11/'Raw Data'!B4 -> 0.23333333 | C7: ='Raw Data'!C11/'Raw Data'!C4 -> 0.24 | D7: ='Raw Data'!D11/'Raw Data'!D4 -> 0.255 | E7: ='Raw Data'!E11/'Raw Data'!E4 -> 0.27454545 | F7: ='Raw Data'!F11/'Raw Data'!F4 -> 0.275
A8: (-) Interest | B8: ='Raw Data'!B7/'Raw Data'!B4 -> 0.0055555556 | C8: ='Raw Data'!C7/'Raw Data'!C4 -> 0.0052631579 | D8: ='Raw Data'!D7/'Raw Data'!D4 -> 0.006 | E8: ='Raw Data'!E7/'Raw Data'!E4 -> 0.0059090909 | F8: ='Raw Data'!F7/'Raw Data'!F4 -> 0.0058333333
A9: (-) Tax | B9: ='Raw Data'!B14/'Raw Data'!B4 -> 0.056944444 | C9: ='Raw Data'!C14/'Raw Data'!C4 -> 0.058684211 | D9: ='Raw Data'!D14/'Raw Data'!D4 -> 0.06225 | E9: ='Raw Data'!E14/'Raw Data'!E4 -> 0.067159091 | F9: ='Raw Data'!F14/'Raw Data'!F4 -> 0.067291667
A10: Net Profit | B10: ='Raw Data'!B15/'Raw Data'!B4 -> 0.17083333 | C10: ='Raw Data'!C15/'Raw Data'!C4 -> 0.17605263 | D10: ='Raw Data'!D15/'Raw Data'!D4 -> 0.18675 | E10: ='Raw Data'!E15/'Raw Data'!E4 -> 0.20147727 | F10: ='Raw Data'!F15/'Raw Data'!F4 -> 0.201875
A12: Question 5: Comparative Income Statement (₹ Crores + YoY % Change)
A13: Item | B13: FY20 | C13: FY21 | D13: YoY% | E13: FY22 | F13: YoY% | G13: FY23 | H13: YoY% | I13: FY24 | J13: YoY% | K13: CAGR
A14: Revenue | B14: ='Raw Data'!B4 -> 90000 | C14: ='Raw Data'!C4 -> 95000 | D14: =(C14-B14)/B14 -> 0.055555556 | E14: ='Raw Data'!D4 -> 100000 | F14: =(E14-C14)/C14 -> 0.052631579 | G14: ='Raw Data'!E4 -> 110000 | H14: =(G14-E14)/E14 -> 0.1 | I14: ='Raw Data'!F4 -> 120000 | J14: =(I14-G14)/G14 -> 0.090909091 | K14: =(I14/B14)^(1/4)-1 -> 0.074569932
A15: Operating Expenses | B15: ='Raw Data'!B5 -> 65000 | C15: ='Raw Data'!C5 -> 68000 | D15: =(C15-B15)/B15 -> 0.046153846 | E15: ='Raw Data'!D5 -> 70000 | F15: =(E15-C15)/C15 -> 0.029411765 | G15: ='Raw Data'!E5 -> 75000 | H15: =(G15-E15)/E15 -> 0.071428571 | I15: ='Raw Data'!F5 -> 82000 | J15: =(I15-G15)/G15 -> 0.093333333 | K15: =(I15/B15)^(1/4)-1 -> 0.05980295
A16: Depreciation | B16: ='Raw Data'!B6 -> 4000 | C16: ='Raw Data'!C6 -> 4200 | D16: =(C16-B16)/B16 -> 0.05 | E16: ='Raw Data'!D6 -> 4500 | F16: =(E16-C16)/C16 -> 0.071428571 | G16: ='Raw Data'!E6 -> 4800 | H16: =(G16-E16)/E16 -> 0.066666667 | I16: ='Raw Data'!F6 -> 5000 | J16: =(I16-G16)/G16 -> 0.041666667 | K16: =(I16/B16)^(1/4)-1 -> 0.057371263
A17: EBIT | B17: ='Raw Data'!B11 -> 21000 | C17: ='Raw Data'!C11 -> 22800 | D17: =(C17-B17)/B17 -> 0.085714286 | E17: ='Raw Data'!D11 -> 25500 | F17: =(E17-C17)/C17 -> 0.11842105 | G17: ='Raw Data'!E11 -> 30200 | H17: =(G17-E17)/E17 -> 0.18431373 | I17: ='Raw Data'!F11 -> 33000 | J17: =(I17-G17)/G17 -> 0.092715232 | K17: =(I17/B17)^(1/4)-1 -> 0.11962777
A18: Interest | B18: ='Raw Data'!B7 -> 500 | C18: ='Raw Data'!C7 -> 500 | D18: =(C18-B18)/B18 -> 0 | E18: ='Raw Data'!D7 -> 600 | F18: =(E18-C18)/C18 -> 0.2 | G18: ='Raw Data'!E7 -> 650 | H18: =(G18-E18)/E18 -> 0.083333333 | I18: ='Raw Data'!F7 -> 700 | J18: =(I18-G18)/G18 -> 0.076923077 | K18: =(I18/B18)^(1/4)-1 -> 0.087757306
A19: Net Profit | B19: ='Raw Data'!B15 -> 15375 | C19: ='Raw Data'!C15 -> 16725 | D19: =(C19-B19)/B19 -> 0.087804878 | E19: ='Raw Data'!D15 -> 18675 | F19: =(E19-C19)/C19 -> 0.11659193 | G19: ='Raw Data'!E15 -> 22162.5 | H19: =(G19-E19)/E19 -> 0.18674699 | I19: ='Raw Data'!F15 -> 24225 | J19: =(I19-G19)/G19 -> 0.093062606 | K19: =(I19/B19)^(1/4)-1 -> 0.12037179

Sheet Financial Ratios
A1: Question 6: FINANCIAL RATIOS (FY 2020 – FY 2024)
A2: Ratio | B2: FY 2020 | C2: FY 2021 | D2: FY 2022 | E2: FY 2023 | F2: FY 2024
A3: LIQUIDITY
A4: Current Ratio | B4: ='Raw Data'!B21/'Raw Data'!B20 -> 0.5 | C4: ='Raw Data'!C21/'Raw Data'!C20 -> 0.54545455 | D4: ='Raw Data'!D21/'Raw Data'!D20 -> 0.65217391 | E4: ='Raw Data'!E21/'Raw Data'!E20 -> 0.72 | F4: ='Raw Data'!F21/'Raw Data'!F20 -> 0.74074074
A5: Quick Ratio | B5: ='Raw Data'!B21/'Raw Data'!B20 -> 0.5 | C5: ='Raw Data'!C21/'Raw Data'!C20 -> 0.54545455 | D5: ='Raw Data'!D21/'Raw Data'!D20 -> 0.65217391 | E5: ='Raw Data'!E21/'Raw Data'!E20 -> 0.72 | F5: ='Raw Data'!F21/'Raw Data'!F20 -> 0.74074074
A6: PROFITABILITY
A7: Operating Margin | B7: ='Raw Data'!B11/'Raw Data'!B4 -> 0.23333333 | C7: ='Raw Data'!C11/'Raw Data'!C4 -> 0.24 | D7: ='Raw Data'!D11/'Raw Data'!D4 -> 0.255 | E7: ='Raw Data'!E11/'Raw Data'!E4 -> 0.27454545 | F7: ='Raw Data'!F11/'Raw Data'!F4 -> 0.275
A8: Net Profit Margin | B8: ='Raw Data'!B15/'Raw Data'!B4 -> 0.17083333 | C8: ='Raw Data'!C15/'Raw Data'!C4 -> 0.17605263 | D8: ='Raw Data'!D15/'Raw Data'!D4 -> 0.18675 | E8: ='Raw Data'!E15/'Raw Data'!E4 -> 0.20147727 | F8: ='Raw Data'!F15/'Raw Data'!F4 -> 0.201875
A9: Return on Equity (ROE) | B9: ='Raw Data'!B15/'Raw Data'!B22 -> 0.15375 | C9: ='Raw Data'!C15/'Raw Data'!C22 -> 0.15486111 | D9: ='Raw Data'!D15/'Raw Data'!D22 -> 0.15961538 | E9: ='Raw Data'!E15/'Raw Data'!E22 -> 0.17048077 | F9: ='Raw Data'!F15/'Raw Data'!F22 -> 0.16940559
A10: LEVERAGE
A11: Debt to Equity Ratio | B11: ='Raw Data'!B20/'Raw Data'!B22 -> 0.2 | C11: ='Raw Data'!C20/'Raw Data'!C22 -> 0.2037037 | D11: ='Raw Data'!D20/'Raw Data'!D22 -> 0.1965812 | E11: ='Raw Data'!E20/'Raw Data'!E22 -> 0.19230769 | F11: ='Raw Data'!F20/'Raw Data'!F22 -> 0.18881119
A12: Interest Coverage Ratio | B12: ='Raw Data'!B11/'Raw Data'!B7 -> 42 | C12: ='Raw Data'!C11/'Raw Data'!C7 -> 45.6 | D12: ='Raw Data'!D11/'Raw Data'!D7 -> 42.5 | E12: ='Raw Data'!E11/'Raw Data'!E7 -> 46.461538 | F12: ='Raw Data'!F11/'Raw Data'!F7 -> 47.142857

Sheet Trend Analysis
A1: Question 7: TREND ANALYSIS (FY 2020 – FY 2024)
A2: Metric | B2: FY 2020 | C2: FY 2021 | D2: FY 2022 | E2: FY 2023 | F2: FY 2024
A3: Revenue (₹ Cr) | B3: ='Raw Data'!B4 -> 90000 | C3: ='Raw Data'!C4 -> 95000 | D3: ='Raw Data'!D4 -> 100000 | E3: ='Raw Data'!E4 -> 110000 | F3: ='Raw Data'!F4 -> 120000
A4: YoY Revenue Growth | B4: 0 | C4: =C3/B3-1 -> 0.055555556 | D4: =D3/C3-1 -> 0.052631579 | E4: =E3/D3-1 -> 0.1 | F4: =F3/E3-1 -> 0.090909091
A5: EBIT (₹ Cr) | B5: ='Raw Data'!B11 -> 21000 | C5: ='Raw Data'!C11 -> 22800 | D5: ='Raw Data'!D11 -> 25500 | E5: ='Raw Data'!E11 -> 30200 | F5: ='Raw Data'!F11 -> 33000
A6: Net Profit (₹ Cr) | B6: ='Raw Data'!B15 -> 15375 | C6: ='Raw Data'!C15 -> 16725 | D6: ='Raw Data'!D15 -> 18675 | E6: ='Raw Data'!E15 -> 22162.5 | F6: ='Raw Data'!F15 -> 24225
A7: Operating Margin | B7: ='Raw Data'!B11/'Raw Data'!B4 -> 0.23333333 | C7: ='Raw Data'!C11/'Raw Data'!C4 -> 0.24 | D7: ='Raw Data'!D11/'Raw Data'!D4 -> 0.255 | E7: ='Raw Data'!E11/'Raw Data'!E4 -> 0.27454545 | F7: ='Raw Data'!F11/'Raw Data'!F4 -> 0.275
A8: Net Profit Margin | B8: ='Raw Data'!B15/'Raw Data'!B4 -> 0.17083333 | C8: ='Raw Data'!C15/'Raw Data'!C4 -> 0.17605263 | D8: ='Raw Data'!D15/'Raw Data'!D4 -> 0.18675 | E8: ='Raw Data'!E15/'Raw Data'!E4 -> 0.20147727 | F8: ='Raw Data'!F15/'Raw Data'!F4 -> 0.201875
A10: Trend | B10: Observation
A11: Revenue Trend | B11: Revenue grew from ₹90,000 Cr (FY20) to ₹1,20,000 Cr (FY24) CAGR ~7.5%. Growth accelerated in FY23 (+10%) indicating strong demand momentum.
A12: Profitability Trend | B12: Net Profit rose from ₹15,375 Cr to ₹24,225 Cr (CAGR ~12%). Margins expanded from 17.1% to 20.2%, improving operational efficiency.
A13: OPEX Trend | B13: OPEX as % of revenue improved from 72.2% (FY20) to 68.3% (FY24), though FY24 saw a slight widening, cost management requires monitoring.
A14: Overall View | B14: Healthy growth with expanding margins. Trends are broadly positive, a growing, profitable enterprise with improving efficiency.

Sheet 3-Statement Model
A1: SECTION 3 - Questions 8 & 9: INTEGRATED THREE-STATEMENT MODEL (₹ Crores)
A2: Income Statement
B3: FY 2020 | C3: FY 2021 | D3: FY 2022 | E3: FY 2023 | F3: FY 2024
A4: Revenue | B4: ='Raw Data'!B4 -> 90000 | C4: ='Raw Data'!C4 -> 95000 | D4: ='Raw Data'!D4 -> 100000 | E4: ='Raw Data'!E4 -> 110000 | F4: ='Raw Data'!F4 -> 120000
A5: (-) Operating Exp. | B5: ='Raw Data'!B5 -> 65000 | C5: ='Raw Data'!C5 -> 68000 | D5: ='Raw Data'!D5 -> 70000 | E5: ='Raw Data'!E5 -> 75000 | F5: ='Raw Data'!F5 -> 82000
A6: (-) Depreciation | B6: ='Raw Data'!B6 -> 4000 | C6: ='Raw Data'!C6 -> 4200 | D6: ='Raw Data'!D6 -> 4500 | E6: ='Raw Data'!E6 -> 4800 | F6: ='Raw Data'!F6 -> 5000
A7: EBIT | B7: =B4-B5-B6 -> 21000 | C7: =C4-C5-C6 -> 22800 | D7: =D4-D5-D6 -> 25500 | E7: =E4-E5-E6 -> 30200 | F7: =F4-F5-F6 -> 33000
A8: (-) Interest | B8: ='Raw Data'!B7 -> 500 | C8: ='Raw Data'!C7 -> 500 | D8: ='Raw Data'!D7 -> 600 | E8: ='Raw Data'!E7 -> 650 | F8: ='Raw Data'!F7 -> 700
A9: EBT | B9: =B7-B8 -> 20500 | C9: =C7-C8 -> 22300 | D9: =D7-D8 -> 24900 | E9: =E7-E8 -> 29550 | F9: =F7-F8 -> 32300
A10: (-) Tax @ 25% | B10: =B9*'Raw Data'!B8 -> 5125 | C10: =C9*'Raw Data'!C8 -> 5575 | D10: =D9*'Raw Data'!D8 -> 6225 | E10: =E9*'Raw Data'!E8 -> 7387.5 | F10: =F9*'Raw Data'!F8 -> 8075
A11: Net Profit | B11: =B9-B10 -> 15375 | C11: =C9-C10 -> 16725 | D11: =D9-D10 -> 18675 | E11: =E9-E10 -> 22162.5 | F11: =F9-F10 -> 24225
A13: Balance Sheet
B14: FY 2020 | C14: FY 2021 | D14: FY 2022 | E14: FY 2023 | F14: FY 2024
A15: Total Assets | B15: ='Raw Data'!B19 -> 120000 | C15: ='Raw Data'!C19 -> 130000 | D15: ='Raw Data'!D19 -> 140000 | E15: ='Raw Data'!E19 -> 155000 | F15: ='Raw Data'!F19 -> 170000
A16: Total Debt | B16: ='Raw Data'!B20 -> 20000 | C16: ='Raw Data'!C20 -> 22000 | D16: ='Raw Data'!D20 -> 23000 | E16: ='Raw Data'!E20 -> 25000 | F16: ='Raw Data'!F20 -> 27000
A17: Cash & Equivalents | B17: ='Raw Data'!B21 -> 10000 | C17: ='Raw Data'!C21 -> 12000 | D17: ='Raw Data'!D21 -> 15000 | E17: ='Raw Data'!E21 -> 18000 | F17: ='Raw Data'!F21 -> 20000
A18: Total Equity | B18: ='Raw Data'!B22 -> 100000 | C18: ='Raw Data'!C22 -> 108000 | D18: ='Raw Data'!D22 -> 117000 | E18: ='Raw Data'!E22 -> 130000 | F18: ='Raw Data'!F22 -> 143000
A19: Retained Earnings* | B19: =40000+B11 -> 55375 | C19: =B19+C11 -> 72100 | D19: =C19+D11 -> 90775 | E19: =D19+E11 -> 112937.5 | F19: =E19+F11 -> 137162.5
A20: * Opening RE assumed ₹40,000 Cr (FY19); all profits retained.
A22: Cash Flow Statement (Indirect Method)
B23: FY 2020 | C23: FY 2021 | D23: FY 2022 | E23: FY 2023 | F23: FY 2024
A24: Net Profit | B24: =B11 -> 15375 | C24: =C11 -> 16725 | D24: =D11 -> 18675 | E24: =E11 -> 22162.5 | F24: =F11 -> 24225
A25: (+) Depreciation | B25: ='Raw Data'!B6 -> 4000 | C25: ='Raw Data'!C6 -> 4200 | D25: ='Raw Data'!D6 -> 4500 | E25: ='Raw Data'!E6 -> 4800 | F25: ='Raw Data'!F6 -> 5000
A26: Cash Flow from Ops (CFO) | B26: =B24+B25 -> 19375 | C26: =C24+C25 -> 20925 | D26: =D24+D25 -> 23175 | E26: =E24+E25 -> 26962.5 | F26: =F24+F25 -> 29225
A27: Cash Flow from Inv (CFI) | B27: =-20000 -> -20000 | C27: =-10000 -> -10000 | D27: =-10000 -> -10000 | E27: =-15000 -> -15000 | F27: =-15000 -> -15000
A28: Cash Flow from Fin (CFF) | B28: =2000 -> 2000 | C28: =2000 -> 2000 | D28: =1000 -> 1000 | E28: =2000 -> 2000 | F28: =2000 -> 2000
A29: Net Change in Cash | B29: =B26+B27+B28 -> 1375 | C29: =C26+C27+C28 -> 12925 | D29: =D26+D27+D28 -> 14175 | E29: =E26+E27+E28 -> 13962.5 | F29: =F26+F27+F28 -> 16225
A30: Closing Cash (Given) | B30: ='Raw Data'!B21 -> 10000 | C30: ='Raw Data'!C21 -> 12000 | D30: ='Raw Data'!D21 -> 15000 | E30: ='Raw Data'!E21 -> 18000 | F30: ='Raw Data'!F21 -> 20000

Sheet Forecasting
A1: SECTION 4 - Questions 10 & 11: FORECASTING (FY 2020 – FY 2029, ₹ Crores)
A2: Forecast Assumptions
A3: Assumption | B3: Value
A4: Revenue Growth Rate | B4: 0.075
A5: OPEX as % of Revenue | B5: 0.68
A6: Depreciation Growth p.a. | B6: 0.04
A7: Interest Growth p.a. | B7: 0.035
A8: Tax Rate | B8: ='Raw Data'!B8 -> 0.25
A9: Forecast Table
A10: Metric | B10: FY20 | C10: FY21 | D10: FY22 | E10: FY23 | F10: FY24 | G10: FY25E | H10: FY26E | I10: FY27E | J10: FY28E | K10: FY29E
A11: Revenue | B11: ='Raw Data'!B4 -> 90000 | C11: ='Raw Data'!C4 -> 95000 | D11: ='Raw Data'!D4 -> 100000 | E11: ='Raw Data'!E4 -> 110000 | F11: ='Raw Data'!F4 -> 120000 | G11: =F11*(1+$B$4) -> 129000 | H11: =G11*(1+$B$4) -> 138675 | I11: =H11*(1+$B$4) -> 149075.62 | J11: =I11*(1+$B$4) -> 160256.3 | K11: =J11*(1+$B$4) -> 172275.52
A12: Operating Expenses | B12: ='Raw Data'!B5 -> 65000 | C12: ='Raw Data'!C5 -> 68000 | D12: ='Raw Data'!D5 -> 70000 | E12: ='Raw Data'!E5 -> 75000 | F12: ='Raw Data'!F5 -> 82000 | G12: =G11*$B$5 -> 87720 | H12: =H11*$B$5 -> 94299 | I12: =I11*$B$5 -> 101371.43 | J12: =J11*$B$5 -> 108974.28 | K12: =K11*$B$5 -> 117147.35
A13: Depreciation | B13: ='Raw Data'!B6 -> 4000 | C13: ='Raw Data'!C6 -> 4200 | D13: ='Raw Data'!D6 -> 4500 | E13: ='Raw Data'!E6 -> 4800 | F13: ='Raw Data'!F6 -> 5000 | G13: =F13*(1+$B$6) -> 5200 | H13: =G13*(1+$B$6) -> 5408 | I13: =H13*(1+$B$6) -> 5624.32 | J13: =I13*(1+$B$6) -> 5849.2928 | K13: =J13*(1+$B$6) -> 6083.2645
A14: EBIT | B14: ='Raw Data'!B11 -> 21000 | C14: ='Raw Data'!C11 -> 22800 | D14: ='Raw Data'!D11 -> 25500 | E14: ='Raw Data'!E11 -> 30200 | F14: ='Raw Data'!F11 -> 33000 | G14: =G11-G12-G13 -> 36080 | H14: =H11-H12-H13 -> 38968 | I14: =I11-I12-I13 -> 42079.88 | J14: =J11-J12-J13 -> 45432.722 | K14: =K11-K12-K13 -> 49044.902
A15: Interest | B15: ='Raw Data'!B7 -> 500 | C15: ='Raw Data'!C7 -> 500 | D15: ='Raw Data'!D7 -> 600 | E15: ='Raw Data'!E7 -> 650 | F15: ='Raw Data'!F7 -> 700 | G15: =F15*(1+$B$7) -> 724.5 | H15: =G15*(1+$B$7) -> 749.8575 | I15: =H15*(1+$B$7) -> 776.10251 | J15: =I15*(1+$B$7) -> 803.2661 | K15: =J15*(1+$B$7) -> 831.38041
A16: Net Profit | B16: ='Raw Data'!B15 -> 15375 | C16: ='Raw Data'!C15 -> 16725 | D16: ='Raw Data'!D15 -> 18675 | E16: ='Raw Data'!E15 -> 22162.5 | F16: ='Raw Data'!F15 -> 24225 | G16: =(G14-G15)*(1-$B$8) -> 26516.625 | H16: =(H14-H15)*(1-$B$8) -> 28663.607 | I16: =(I14-I15)*(1-$B$8) -> 30977.833 | J16: =(J14-J15)*(1-$B$8) -> 33472.092 | K16: =(K14-K15)*(1-$B$8) -> 36160.141
A17: Cash Flow from Ops | B17: =B16+'Raw Data'!B6 -> 19375 | C17: =C16+'Raw Data'!C6 -> 20925 | D17: =D16+'Raw Data'!D6 -> 23175 | E17: =E16+'Raw Data'!E6 -> 26962.5 | F17: =F16+'Raw Data'!F6 -> 29225 | G17: =G16+G13 -> 31716.625 | H17: =H16+H13 -> 34071.607 | I17: =I16+I13 -> 36602.153 | J17: =J16+J13 -> 39321.385 | K17: =K16+K13 -> 42243.405

Sheet DCF Valuation
A1: SECTION 5 - Questions 12–18: DCF VALUATION MODEL (₹ Crores)
A2: Step 1: Cost of Equity - CAPM (Question 14)
A3: Item | B3: Value
A4: Risk-Free Rate (Rf) | B4: ='Raw Data'!B26 -> 0.06
A5: Market Return (Rm) | B5: ='Raw Data'!B27 -> 0.12
A6: Equity Beta (β) | B6: ='Raw Data'!B28 -> 1.1
A7: Cost of Equity (Ke) | B7: =B4+B6*(B5-B4) -> 0.126
A9: Step 2: WACC (Question 15)
A10: Item | B10: Value
A11: Cost of Debt (Kd) | B11: ='Raw Data'!B29 -> 0.08
A12: Tax Rate | B12: ='Raw Data'!B8 -> 0.25
A13: Total Debt (FY2024) | B13: ='Raw Data'!F20 -> 27000
A14: Total Equity (FY2024) | B14: ='Raw Data'!F22 -> 143000
A15: Total Capital (V = D + E) | B15: =B13+B14 -> 170000
A16: Debt Weight (D/V) | B16: =B13/B15 -> 0.15882353
A17: Equity Weight (E/V) | B17: =B14/B15 -> 0.84117647
A18: WACC | B18: =B11*(1-B12)*B16+B7*B17 -> 0.11551765
A20: Step 3: NOPAT & Unlevered Free Cash Flow (Questions 12–13)
A21: Item | B21: Value
A22: EBIT (FY2024) | B22: ='Raw Data'!F11 -> 33000
A23: NOPAT = EBIT × (1 − Tax Rate) | B23: =B22*(1-B12) -> 24750
A24: (+) Depreciation | B24: ='Raw Data'!F6 -> 5000
A25: (−) CapEx (proxy: 1.5 × Depreciation) | B25: =B24*1.5 -> 7500
A26: Unlevered FCF (FY2024) | B26: =B23+B24-B25 -> 22250
A28: Step 4: Projected Free Cash Flows & Present Value
A29: Item | B29: Value
A30: FCF Year 1 (FY25E) | B30: =Forecasting!G14*(1-B12)+Forecasting!G13-Forecasting!G13*1.5 -> 24460
A32: FCF Year 2 (FY26E) | B32: =Forecasting!H14*(1-B12)+Forecasting!H13-Forecasting!H13*1.5 -> 26522
A34: FCF Year 3 (FY27E) | B34: =Forecasting!I14*(1-B12)+Forecasting!I13-Forecasting!I13*1.5 -> 28747.75
A36: FCF Year 4 (FY28E) | B36: =Forecasting!J14*(1-B12)+Forecasting!J13-Forecasting!J13*1.5 -> 31149.895
A38: FCF Year 5 (FY29E) | B38: =Forecasting!K14*(1-B12)+Forecasting!K13-Forecasting!K13*1.5 -> 33742.044
A40: PV of FCFs (Sum) | B40: =B30/(1+B18)^1+B32/(1+B18)^2+B34/(1+B18)^3+B36/(1+B18)^4+B38/(1+B18)^5 -> 103600.54
A42: Step 5: Terminal Value & Enterprise Value (Questions 16–17)
A43: Item | B43: Value
A44: Terminal Growth Rate (g) | B44: ='Raw Data'!B31 -> 0.05
A45: FCF Year 5 (FY29E) | B45: =B38 -> 33742.044
A46: Terminal Value | B46: =B45*(1+B44)/(B18-B44) -> 540757.3
A47: PV of Terminal Value | B47: =B46/(1+B18)^5 -> 313054.66
A48: Enterprise Value (DCF) | B48: =B40+B47 -> 416655.2
A50: Step 6: Equity Value & Value per Share (Question 18)
...

Sheet Other Valuations
A1: SECTION 6 - Questions 19–20: BOOK VALUE PER SHARE
A2: Question 19: Book Value per Share
A3: Item | B3: Value
A4: Total Equity (FY2024) | B4: ='Raw Data'!F22 -> 143000
A5: Shares Outstanding (Crores) | B5: ='Raw Data'!B30 -> 420
A6: Book Value per Share (₹) | B6: =B4/B5 -> 340.47619
A8: Question 20: Adjusted Book Value Method
A9: The Adjusted Book Value method restates assets and liabilities at fair market or replacement values rather than historical cost. Intangibles like brand, IP, and goodwill are added; obsolete assets are written down. For Infosys (IT services), intangible assets such as workforce and client relationships often exceed book assets, making this method an underestimate of true value.

Sheet EBITDA & EV
A1: SECTION 7 - Question 21: EBITDA & ENTERPRISE VALUE (₹ Crores)
A2: EBITDA Calculation
A3: Item | B3: Value
A4: Revenue (FY2024) | B4: ='Raw Data'!F4 -> 120000
A5: (-) Operating Expenses | B5: ='Raw Data'!F5 -> 82000
A6: EBIT | B6: ='Raw Data'!F11 -> 33000
A7: (+) Depreciation | B7: ='Raw Data'!F6 -> 5000
A8: EBITDA | B8: =B6+B7 -> 38000
A10: Enterprise Value Calculation
A11: Item | B11: Value
A12: Total Assets (FY2024) | B12: ='Raw Data'!F19 -> 170000
A13: (+) Total Debt | B13: ='Raw Data'!F20 -> 27000
A14: (-) Cash & Equivalents | B14: ='Raw Data'!F21 -> 20000
A15: Enterprise Value (EV) | B15: =B12+B13-B14 -> 177000
A16: Implied EV/EBITDA | B16: =B15/B8 -> 4.6578947

Sheet Relative Valuation
A1: SECTION 8 - Question 22: RELATIVE VALUATION - Comparable Companies (₹ Crores)
A2: EV/EBITDA Method
A3: Item | B3: Value
A4: TCS - EV/EBITDA | B4: 25
A5: Wipro - EV/EBITDA | B5: 18
A6: HCL Tech - EV/EBITDA | B6: 20
A7: Peer Average EV/EBITDA | B7: =AVERAGE(B4:B6) -> 21
A8: Infosys EBITDA (FY2024) | B8: ='EBITDA & EV'!B8 -> 38000
A9: Implied EV (Peer × EBITDA) | B9: =B7*B8 -> 798000
A10: (-) Debt + Cash | B10: =-'Raw Data'!F20+'Raw Data'!F21 -> -7000
A11: Implied Equity Value | B11: =B9+B10 -> 791000
A12: Value per Share - EV/EBITDA (₹) | B12: =B11/'Raw Data'!B30 -> 1883.3333
A14: P/E Method
A15: Item | B15: Value
A16: TCS - P/E | B16: 30
A17: Wipro - P/E | B17: 22
A18: HCL Tech - P/E | B18: 24
A19: Peer Average P/E | B19: =AVERAGE(B16:B18) -> 25.333333
A20: EPS (FY2024) | B20: ='Raw Data'!F15/'Raw Data'!B30 -> 57.678571
A21: Value per Share - P/E (₹) | B21: =B19*B20 -> 1461.1905

Sheet Replacement Cost Model
A1: SECTION 9 - Questions 23–24: REPLACEMENT COST MODEL (₹ Crores)
A2: Question 23: Explanation
A3: The Replacement Cost Method estimates how much it would cost at current prices to recreate the company's entire asset base from scratch. Unlike DCF (income-based) or P/E (market-based), it values the firm based on the physical cost of its assets. Commonly used in insurance, real estate, and capital-intensive sectors. For Infosys, this understates value as human capital and software - the firm's key assets - are not on the balance sheet.
A7: Question 24: Replacement Value Calculation
A8: Item | B8: Value
A9: Book Value of Total Assets (FY2024) | B9: ='Raw Data'!F19 -> 170000
A10: Inflation Adjustment (+15%) | B10: 0.15
A11: Replacement Value of Assets (₹ Cr) | B11: =B9*(1+B10) -> 195500

Sheet Beta Analysis
A1: SECTION 10 - Questions 25–26: BETA ANALYSIS
A2: Question 25: Equity Beta vs Asset Beta - Concepts
A3: Equity Beta (Levered) | B3: Measures total risk borne by equity holders - includes both business (operating) risk and financial risk due to leverage. Higher debt = higher equity beta. Given as 1.1 in this project.
A5: Asset Beta (Unlevered) | B5: Measures pure business (operating) risk - strips out financial leverage. Two firms with identical operations but different capital structures have the same asset beta but different equity betas. Used to compare risk across firms.
A8: Question 26: Unlevered Beta & Re-Levered Beta
A9: Item | B9: Value
A10: Equity Beta (β_L) | B10: ='Raw Data'!B28 -> 1.1
A11: Total Debt (FY2024) | B11: ='Raw Data'!F20 -> 27000
A12: Total Equity (FY2024) | B12: ='Raw Data'!F22 -> 143000
A13: D/E Ratio | B13: =B11/B12 -> 0.18881119
A14: Tax Rate | B14: ='Raw Data'!B8 -> 0.25
A15: Unlevered Beta (Asset Beta) | B15: =B10/(1+(1-B14)*B13) -> 0.96355283
A16: Re-Levered Beta (at same D/E) | B16: =B15*(1+(1-B14)*B13) -> 1.1

Sheet Startup Valuation
A1: SECTION 11 - Question 27: STARTUP VALUATION vs MATURE COMPANIES
A2: Aspect | B2: Explanation
A3: No Historical Cash Flows | B3: Start-ups often have zero or negative revenue and cash flows, making DCF unreliable - projections are highly speculative. For mature companies like Infosys, DCF works because there is a proven track record of earnings and cash flows.
A5: Methods Used for Start-ups | B5: Common approaches: VC Method (discount projected exit value at 30–50% hurdle rate), Berkus Method (assign value to key milestones), Scorecard Method (compare to funded peers), or recent funding round comparables.
A7: VC Method | B7: Estimate the firm's exit value (e.g., IPO in 5 years) using industry P/E × projected earnings. Discount back at the VC's required return (40%) to account for high failure probability - most start-ups fail.
A9: Key Differences | B9: Mature companies - valued on DCF, P/E, EV/EBITDA using stable margins and earnings. Start-ups - valued on potential, team, market size, and runway. No stable margins, often pre-revenue, with high binary risk.

Sheet Sensitivity Analysis
A1: SECTION 12 - Question 28: SENSITIVITY ANALYSIS - Value per Share (₹)
A2: Rows = WACC | Columns = Terminal Growth Rate (g)
A3: WACC ↓ / g → | B3: 0.03 | C3: 0.04 | D3: 0.05 | E3: 0.06
A4: 0.08 | B4: =IF($A4<=$B3,"N/A",(('DCF Valuation'!B30/($A4)^1+'DCF Valuation'!B32/($A4)^2+'DCF Valuation'!B34/($A4)^3+'DCF Valuation'!B36/($A4)^4+'DCF Valuation'!B38/($A4)^5+('DCF Valuation'!B38*(1+$B3)/($A4-$B3))/($A4)^5)-'Raw Data'!F20+'Raw Data'!F21)/'Raw Data'!B30) -> 5.3152806e+08 | C4: =IF($A4<=$C3,"N/A",(('DCF Valuation'!B30/($A4)^1+'DCF Valuation'!B32/($A4)^2+'DCF Valuation'!B34/($A4)^3+'DCF Valuation'!B36/($A4)^4+'DCF Valuation'!B38/($A4)^5+('DCF Valuation'!B38*(1+$C3)/($A4-$C3))/($A4)^5)-'Raw Data'!F20+'Raw Data'!F21)/'Raw Data'!B30) -> 6.6392134e+08 | D4: =IF($A4<=$D3,"N/A",(('DCF Valuation'!B30/($A4)^1+'DCF Valuation'!B32/($A4)^2+'DCF Valuation'!B34/($A4)^3+'DCF Valuation'!B36/($A4)^4+'DCF Valuation'!B38/($A4)^5+('DCF Valuation'!B38*(1+$D3)/($A4-$D3))/($A4)^5)-'Raw Data'!F20+'Raw Data'!F21)/'Raw Data'!B30) -> 8.8457679e+08 | E4: =IF($A4<=$E3,"N/A",(('DCF Valuation'!B30/($A4)^1+'DCF Valuation'!B32/($A4)^2+'DCF Valuation'!B34/($A4)^3+'DCF Valuation'!B36/($A4)^4+'DCF Valuation'!B38/($A4)^5+('DCF Valuation'!B38*(1+$E3)/($A4-$E3))/($A4)^5)-'Raw Data'!F20+'Raw Data'!F21)/'Raw Data'!B30) -> 1.3258877e+09
A5: 0.09 | B5: =IF($A5<=$B3,"N/A",(('DCF Valuation'!B30/($A5)^1+'DCF Valuation'!B32/($A5)^2+'DCF Valuation'!B34/($A5)^3+'DCF Valuation'!B36/($A5)^4+'DCF Valuation'!B38/($A5)^5+('DCF Valuation'!B38*(1+$B3)/($A5-$B3))/($A5)^5)-'Raw Data'!F20+'Raw Data'!F21)/'Raw Data'!B30) -> 2.4839649e+08 | C5: =IF($A5<=$C3,"N/A",(('DCF Valuation'!B30/($A5)^1+'DCF Valuation'!B32/($A5)^2+'DCF Valuation'!B34/($A5)^3+'DCF Valuation'!B36/($A5)^4+'DCF Valuation'!B38/($A5)^5+('DCF Valuation'!B38*(1+$C3)/($A5-$C3))/($A5)^5)-'Raw Data'!F20+'Raw Data'!F21)/'Raw Data'!B30) -> 2.9782925e+08 | D5: =IF($A5<=$D3,"N/A",(('DCF Valuation'!B30/($A5)^1+'DCF Valuation'!B32/($A5)^2+'DCF Valuation'!B34/($A5)^3+'DCF Valuation'!B36/($A5)^4+'DCF Valuation'!B38/($A5)^5+('DCF Valuation'!B38*(1+$D3)/($A5-$D3))/($A5)^5)-'Raw Data'!F20+'Raw Data'!F21)/'Raw Data'!B30) -> 3.7197837e+08 | E5: =IF($A5<=$E3,"N/A",(('DCF Valuation'!B30/($A5)^1+'DCF Valuation'!B32/($A5)^2+'DCF Valuation'!B34/($A5)^3+'DCF Valuation'!B36/($A5)^4+'DCF Valuation'!B38/($A5)^5+('DCF Valuation'!B38*(1+$E3)/($A5-$E3))/($A5)^5)-'Raw Data'!F20+'Raw Data'!F21)/'Raw Data'!B30) -> 4.9556026e+08
A6: 0.1 | B6: =IF($A6<=$B3,"N/A",(('DCF Valuation'!B30/($A6)^1+'DCF Valuation'!B32/($A6)^2+'DCF Valuation'!B34/($A6)^3+'DCF Valuation'!B36/($A6)^4+'DCF Valuation'!B38/($A6)^5+('DCF Valuation'!B38*(1+$B3)/($A6-$B3))/($A6)^5)-'Raw Data'!F20+'Raw Data'!F21)/'Raw Data'!B30) -> 1.2706273e+08 | C6: =IF($A6<=$C3,"N/A",(('DCF Valuation'!B30/($A6)^1+'DCF Valuation'!B32/($A6)^2+'DCF Valuation'!B34/($A6)^3+'DCF Valuation'!B36/($A6)^4+'DCF Valuation'!B38/($A6)^5+('DCF Valuation'!B38*(1+$C3)/($A6-$C3))/($A6)^5)-'Raw Data'!F20+'Raw Data'!F21)/'Raw Data'!B30) -> 1.4810369e+08 | D6: =IF($A6<=$D3,"N/A",(('DCF Valuation'!B30/($A6)^1+'DCF Valuation'!B32/($A6)^2+'DCF Valuation'!B34/($A6)^3+'DCF Valuation'!B36/($A6)^4+'DCF Valuation'!B38/($A6)^5+('DCF Valuation'!B38*(1+$D3)/($A6-$D3))/($A6)^5)-'Raw Data'!F20+'Raw Data'!F21)/'Raw Data'!B30) -> 1.7756103e+08 | E6: =IF($A6<=$E3,"N/A",(('DCF Valuation'!B30/($A6)^1+'DCF Valuation'!B32/($A6)^2+'DCF Valuation'!B34/($A6)^3+'DCF Valuation'!B36/($A6)^4+'DCF Valuation'!B38/($A6)^5+('DCF Valuation'!B38*(1+$E3)/($A6-$E3))/($A6)^5)-'Raw Data'!F20+'Raw Data'!F21)/'Raw Data'!B30) -> 2.2174704e+08
A7: 0.11 | B7: =IF($A7<=$B3,"N/A",(('DCF Valuation'!B30/($A7)^1+'DCF Valuation'!B32/($A7)^2+'DCF Valuation'!B34/($A7)^3+'DCF Valuation'!B36/($A7)^4+'DCF Valuation'!B38/($A7)^5+('DCF Valuation'!B38*(1+$B3)/($A7-$B3))/($A7)^5)-'Raw Data'!F20+'Raw Data'!F21)/'Raw Data'!B30) -> 69777359 | C7: =IF($A7<=$C3,"N/A",(('DCF Valuation'!B30/($A7)^1+'DCF Valuation'!B32/($A7)^2+'DCF Valuation'!B34/($A7)^3+'DCF Valuation'!B36/($A7)^4+'DCF Valuation'!B38/($A7)^5+('DCF Valuation'!B38*(1+$C3)/($A7-$C3))/($A7)^5)-'Raw Data'!F20+'Raw Data'!F21)/'Raw Data'!B30) -> 79665021 | D7: =IF($A7<=$D3,"N/A",(('DCF Valuation'!B30/($A7)^1+'DCF Valuation'!B32/($A7)^2+'DCF Valuation'!B34/($A7)^3+'DCF Valuation'!B36/($A7)^4+'DCF Valuation'!B38/($A7)^5+('DCF Valuation'!B38*(1+$D3)/($A7-$D3))/($A7)^5)-'Raw Data'!F20+'Raw Data'!F21)/'Raw Data'!B30) -> 92848571 | E7: =IF($A7<=$E3,"N/A",(('DCF Valuation'!B30/($A7)^1+'DCF Valuation'!B32/($A7)^2+'DCF Valuation'!B34/($A7)^3+'DCF Valuation'!B36/($A7)^4+'DCF Valuation'!B38/($A7)^5+('DCF Valuation'!B38*(1+$E3)/($A7-$E3))/($A7)^5)-'Raw Data'!F20+'Raw Data'!F21)/'Raw Data'!B30) -> 1.1130554e+08
A8: 0.12 | B8: =IF($A8<=$B3,"N/A",(('DCF Valuation'!B30/($A8)^1+'DCF Valuation'!B32/($A8)^2+'DCF Valuation'!B34/($A8)^3+'DCF Valuation'!B36/($A8)^4+'DCF Valuation'!B38/($A8)^5+('DCF Valuation'!B38*(1+$B3)/($A8-$B3))/($A8)^5)-'Raw Data'!F20+'Raw Data'!F21)/'Raw Data'!B30) -> 40580418 | C8: =IF($A8<=$C3,"N/A",(('DCF Valuation'!B30/($A8)^1+'DCF Valuation'!B32/($A8)^2+'DCF Valuation'!B34/($A8)^3+'DCF Valuation'!B36/($A8)^4+'DCF Valuation'!B38/($A8)^5+('DCF Valuation'!B38*(1+$C3)/($A8-$C3))/($A8)^5)-'Raw Data'!F20+'Raw Data'!F21)/'Raw Data'!B30) -> 45602703 | D8: =IF($A8<=$D3,"N/A",(('DCF Valuation'!B30/($A8)^1+'DCF Valuation'!B32/($A8)^2+'DCF Valuation'!B34/($A8)^3+'DCF Valuation'!B36/($A8)^4+'DCF Valuation'!B38/($A8)^5+('DCF Valuation'!B38*(1+$D3)/($A8-$D3))/($A8)^5)-'Raw Data'!F20+'Raw Data'!F21)/'Raw Data'!B30) -> 52059927 | E8: =IF($A8<=$E3,"N/A",(('DCF Valuation'!B30/($A8)^1+'DCF Valuation'!B32/($A8)^2+'DCF Valuation'!B34/($A8)^3+'DCF Valuation'!B36/($A8)^4+'DCF Valuation'!B38/($A8)^5+('DCF Valuation'!B38*(1+$E3)/($A8-$E3))/($A8)^5)-'Raw Data'!F20+'Raw Data'!F21)/'Raw Data'!B30) -> 60669560
A11: Interpretation
A12: WACC Effect | B12: A higher WACC (discount rate) reduces the present value of all future cash flows, directly lowering the share value. Moving from 8% to 12% WACC compresses valuation significantly - shows how sensitive value is to cost of capital assumptions.
A13: Growth Effect | B13: A higher terminal growth rate (g) increases the terminal value, raising the share price. However, g must stay below WACC - if g ≥ WACCbreaks down
A14: Key Insight | B14: Infosys valuation is more sensitive to WACC changes than to growth rate changes. Even a 1% rise in WACC cuts value materially. This reinforces the importance of accurate WACC estimation in any DCF model.

Sheet Charts
A1: SECTION 13 - Question 29: DATA VISUALIZATION
A3: Year | B3: Revenue | C3: EBIT | D3: Net Profit | E3: Op Margin | F3: NP Margin
A4: FY 2020 | B4: ='Raw Data'!B4 -> 90000 | C4: ='Raw Data'!B11 -> 21000 | D4: ='Raw Data'!B15 -> 15375 | E4: ='Raw Data'!B11/'Raw Data'!B4 -> 0.23333333 | F4: ='Raw Data'!B15/'Raw Data'!B4 -> 0.17083333
A5: FY 2021 | B5: ='Raw Data'!C4 -> 95000 | C5: ='Raw Data'!C11 -> 22800 | D5: ='Raw Data'!C15 -> 16725 | E5: ='Raw Data'!C11/'Raw Data'!C4 -> 0.24 | F5: ='Raw Data'!C15/'Raw Data'!C4 -> 0.17605263
A6: FY 2022 | B6: ='Raw Data'!D4 -> 100000 | C6: ='Raw Data'!D11 -> 25500 | D6: ='Raw Data'!D15 -> 18675 | E6: ='Raw Data'!D11/'Raw Data'!D4 -> 0.255 | F6: ='Raw Data'!D15/'Raw Data'!D4 -> 0.18675
A7: FY 2023 | B7: ='Raw Data'!E4 -> 110000 | C7: ='Raw Data'!E11 -> 30200 | D7: ='Raw Data'!E15 -> 22162.5 | E7: ='Raw Data'!E11/'Raw Data'!E4 -> 0.27454545 | F7: ='Raw Data'!E15/'Raw Data'!E4 -> 0.20147727
A8: FY 2024 | B8: ='Raw Data'!F4 -> 120000 | C8: ='Raw Data'!F11 -> 33000 | D8: ='Raw Data'!F15 -> 24225 | E8: ='Raw Data'!F11/'Raw Data'!F4 -> 0.275 | F8: ='Raw Data'!F15/'Raw Data'!F4 -> 0.201875

Sheet Final Conclusion
A1: SECTION 14 - Question 30: FINAL CONCLUSION - Is Infosys Fairly Valued?
A2: Valuation Summary
A3: Method | B3: Value per Share (₹)
A4: DCF Valuation | B4: ='DCF Valuation'!B56 -> 975.36952
A5: EV/EBITDA Method | B5: ='Relative Valuation'!B12 -> 1883.3333
A6: P/E Method | B6: ='Relative Valuation'!B21 -> 1461.1905
A7: Book Value per Share | B7: ='Other Valuations'!B6 -> 340.47619
A8: Average Value per Share (₹)
A10: Final Investment View & Conclusion
A11: Question 30: FINAL INVESTMENT VIEW & CONCLUSION
A12: Business Quality | B12: Infosys shows strong revenue growth (5Y CAGR - 7.5%), consistently expanding profitability, and solid cash generation. Leverage is manageable and declining - a hallmark of a financially sound enterprise.
A13: Valuation View | B13: The DCF model yields a conservative value driven by WACC sensitivity. Relative valuation (EV/EBITDA and P/E) gives a higher range, reflecting market premium for quality IT firms. Book value understates value for asset-light businesses.
A14: VERDICT | B14: Based on the complete financial analysis using hypothetical data, Infosys appears FAIRLY VALUED to SLIGHTLY UNDERVALUED. The average of the three primary methods suggests meaningful upside. An investor with a long-term horizon and moderate risk appetite would find the stock attractively priced at or below the average intrinsic value.
A15: Key Risks | B15: 1) OPEX growing faster than revenue in FY2024. 2) High WACC sensitivity - every 1% rise cuts DCF value materially. 3) Currency risk, client concentration, macro demand slowdown. 4) Peer re-rating could affect relative valuation.
