Workbook

Sheet Assumptions
B2: 3 Statement Financial Model
A4: X | B4: Assumptions
B5: Income Statement Assumptions
B6: Units Sold | D6: 400 | E6: 420 | F6: 450 | G6: 475 | H6: 500
B7: Price per Unit | D7: 495.95 | E7: 495.95 | F7: 495.95 | G7: 495.95 | H7: 495.95
B9: COGS as a % of Rev | D9: 0.43 | E9: 0.43 | F9: 0.4 | G9: 0.38 | H9: 0.38
B10: SG&A as a % of Rev | D10: 0.35 | E10: 0.35 | F10: 0.35 | G10: 0.35 | H10: 0.35
B12: Tax Rate | D12: 0.21 | E12: 0.21 | F12: 0.21 | G12: 0.21 | H12: 0.21
B14: Revenue | C14: 158997 | D14: ='Income statement'!C3 -> 198380 | E14: ='Income statement'!D3 -> 208299 | F14: ='Income statement'!E3 -> 223177.5 | G14: ='Income statement'!F3 -> 235576.25 | H14: ='Income statement'!G3 -> 247975
B15: COGS | C15: 75889 | D15: =-'Income statement'!C4 -> 85303.4 | E15: =-'Income statement'!D4 -> 89568.57 | F15: =-'Income statement'!E4 -> 89271 | G15: =-'Income statement'!F4 -> 89518.975 | H15: =-'Income statement'!G4 -> 94230.5
B17: Balance Sheet Assumptions
B18: ='balance sheet'!A4&" as a % of Rev" -> Accounts Receivable as a % of Rev | C18: ='balance sheet'!$B$4/Assumptions!$C$14 -> 0.062120669 | D18: ='balance sheet'!$B$4/Assumptions!$C$14 -> 0.062120669 | E18: ='balance sheet'!$B$4/Assumptions!$C$14 -> 0.062120669 | F18: ='balance sheet'!$B$4/Assumptions!$C$14 -> 0.062120669 | G18: ='balance sheet'!$B$4/Assumptions!$C$14 -> 0.062120669 | H18: ='balance sheet'!$B$4/Assumptions!$C$14 -> 0.062120669
B19: ='balance sheet'!A5&" as a % of COGS" -> Inventory as a % of COGS | C19: ='balance sheet'!$B$5/Assumptions!$C$15 -> 0.11304669 | D19: ='balance sheet'!$B$5/Assumptions!$C$15 -> 0.11304669 | E19: ='balance sheet'!$B$5/Assumptions!$C$15 -> 0.11304669 | F19: ='balance sheet'!$B$5/Assumptions!$C$15 -> 0.11304669 | G19: ='balance sheet'!$B$5/Assumptions!$C$15 -> 0.11304669 | H19: ='balance sheet'!$B$5/Assumptions!$C$15 -> 0.11304669
B20: ='balance sheet'!A10&" as a % of COGS" -> Accounts Payable as a % of COGS | C20: ='balance sheet'!$B$10/Assumptions!$C$15 -> 0.19607585 | D20: ='balance sheet'!$B$10/Assumptions!$C$15 -> 0.19607585 | E20: ='balance sheet'!$B$10/Assumptions!$C$15 -> 0.19607585 | F20: ='balance sheet'!$B$10/Assumptions!$C$15 -> 0.19607585 | G20: ='balance sheet'!$B$10/Assumptions!$C$15 -> 0.19607585 | H20: ='balance sheet'!$B$10/Assumptions!$C$15 -> 0.19607585
B22: Long Term Debt | D22: 40000 | E22: =D22 -> 40000 | F22: =E22 -> 40000 | G22: =F22 -> 40000 | H22: =G22 -> 40000
B23: Interest Expense % | D23: 0.07 | E23: 0.07 | F23: 0.07 | G23: 0.07 | H23: 0.07
B24: Interest Expense | D24: =D22*D23 -> 2800 | E24: =E22*E23 -> 2800 | F24: =F22*F23 -> 2800 | G24: =G22*G23 -> 2800 | H24: =H22*H23 -> 2800
A26: X | B26: Supporting Schedules
B27: Fixed Assets Schedule
B28: Capex | D28: 15000 | E28: 12000 | F28: 10000 | G28: 7500 | H28: 7500
B30: Existing Assets Useful Life (years) | C30: 10
B31: New Assets Useful Life (years) | C31: 10
B32: PP&E 2023 EOP | C32: ='balance sheet'!B7 -> 48990
C34: Capex | D34: 2024 | E34: 2025 | F34: 2026 | G34: 2027 | H34: 2028
C35: {=TRANSPOSE(D28:H28)} -> 15000 | D35: =$C35/$C$31 -> 1500 | E35: =$C35/$C$31 -> 1500 | F35: =$C35/$C$31 -> 1500 | G35: =$C35/$C$31 -> 1500 | H35: =$C35/$C$31 -> 1500
C36: 12000 | E36: =$C36/$C$31 -> 1200 | F36: =$C36/$C$31 -> 1200 | G36: =$C36/$C$31 -> 1200 | H36: =$C36/$C$31 -> 1200
C37: 10000 | F37: =$C37/$C$31 -> 1000 | G37: =$C37/$C$31 -> 1000 | H37: =$C37/$C$31 -> 1000
C38: 7500 | G38: =$C38/$C$31 -> 750 | H38: =$C38/$C$31 -> 750
C39: 7500 | H39: =$C39/$C$31 -> 750
B41: Existing Asset Depreciation | D41: =$C$32/$C$30 -> 4899 | E41: =$C$32/$C$30 -> 4899 | F41: =$C$32/$C$30 -> 4899 | G41: =$C$32/$C$30 -> 4899 | H41: =$C$32/$C$30 -> 4899
B42: New Assets Depreciation | D42: =SUM(D35:D39) -> 1500 | E42: =SUM(E35:E39) -> 2700 | F42: =SUM(F35:F39) -> 3700 | G42: =SUM(G35:G39) -> 4450 | H42: =SUM(H35:H39) -> 5200
B43: Total Depreciation | D43: =SUM(D41:D42) -> 6399 | E43: =SUM(E41:E42) -> 7599 | F43: =SUM(F41:F42) -> 8599 | G43: =SUM(G41:G42) -> 9349 | H43: =SUM(H41:H42) -> 10099
B45: Beginning PPE | D45: =C48 -> 48990 | E45: =D48 -> 57591 | F45: =E48 -> 61992 | G45: =F48 -> 63393 | H45: =G48 -> 61544
B46: Capex | D46: =C35 -> 15000 | E46: =C36 -> 12000 | F46: =C37 -> 10000 | G46: =C38 -> 7500 | H46: =C39 -> 7500
B47: Depreciation | D47: =-D43 -> -6399 | E47: =-E43 -> -7599 | F47: =-F43 -> -8599 | G47: =-G43 -> -9349 | H47: =-H43 -> -10099
B48: Ending PPE | C48: =C32 -> 48990 | D48: =SUM(D45:D47) -> 57591 | E48: =SUM(E45:E47) -> 61992 | F48: =SUM(F45:F47) -> 63393 | G48: =SUM(G45:G47) -> 61544 | H48: =SUM(H45:H47) -> 58945
A50: X | B50: Retained Earnings Schedule
B51: Beginning of Period RE | D51: =C54 -> 2155 | E51: =D54 -> 19366.234 | F51: =E54 -> 34853.39 | G51: =F54 -> 54925.736 | H51: =G54 -> 75576.441
B52: Net Income | D52: ='Income statement'!C12 -> 27211.234 | E52: ='Income statement'!D12 -> 27987.156 | F52: ='Income statement'!E12 -> 35072.346 | G52: ='Income statement'!F12 -> 40650.704 | H52: ='Income statement'!G12 -> 42702.857
B53: Dividends | D53: -10000 | E53: -12500 | F53: -15000 | G53: -20000 | H53: -25000
...

Sheet Income statement
A1: Income Statement
A2: Figures in USD millions | C2: ='balance sheet'!C2 -> 2024 | D2: ='balance sheet'!D2 -> 2025 | E2: ='balance sheet'!E2 -> 2026 | F2: ='balance sheet'!F2 -> 2027 | G2: ='balance sheet'!G2 -> 2028
A3: Revenue | C3: =Assumptions!D6*Assumptions!D7 -> 198380 | D3: =Assumptions!E6*Assumptions!E7 -> 208299 | E3: =Assumptions!F6*Assumptions!F7 -> 223177.5 | F3: =Assumptions!G6*Assumptions!G7 -> 235576.25 | G3: =Assumptions!H6*Assumptions!H7 -> 247975
A4: COGS | C4: =-Assumptions!D9*'Income statement'!C3 -> -85303.4 | D4: =-Assumptions!E9*'Income statement'!D3 -> -89568.57 | E4: =-Assumptions!F9*'Income statement'!E3 -> -89271 | F4: =-Assumptions!G9*'Income statement'!F3 -> -89518.975 | G4: =-Assumptions!H9*'Income statement'!G3 -> -94230.5
A5: Gross Profit | C5: =SUM(C3:C4) -> 113076.6 | D5: =SUM(D3:D4) -> 118730.43 | E5: =SUM(E3:E4) -> 133906.5 | F5: =SUM(F3:F4) -> 146057.27 | G5: =SUM(G3:G4) -> 153744.5
A6: SG&A | C6: =-C3*Assumptions!D10 -> -69433 | D6: =-D3*Assumptions!E10 -> -72904.65 | E6: =-E3*Assumptions!F10 -> -78112.125 | F6: =-F3*Assumptions!G10 -> -82451.688 | G6: =-G3*Assumptions!H10 -> -86791.25
A7: Depreciation | C7: =-Assumptions!D43 -> -6399 | D7: =-Assumptions!E43 -> -7599 | E7: =-Assumptions!F43 -> -8599 | F7: =-Assumptions!G43 -> -9349 | G7: =-Assumptions!H43 -> -10099
A8: Operating Profit | C8: =SUM(C5:C7) -> 37244.6 | D8: =SUM(D5:D7) -> 38226.78 | E8: =SUM(E5:E7) -> 47195.375 | F8: =SUM(F5:F7) -> 54256.587 | G8: =SUM(G5:G7) -> 56854.25
A9: Interest | C9: =-revolver!C18 -> -2800 | D9: =-revolver!D18 -> -2800 | E9: =-revolver!E18 -> -2800 | F9: =-revolver!F18 -> -2800 | G9: =-revolver!G18 -> -2800
A10: Earnings Before Tax | C10: =SUM(C8:C9) -> 34444.6 | D10: =SUM(D8:D9) -> 35426.78 | E10: =SUM(E8:E9) -> 44395.375 | F10: =SUM(F8:F9) -> 51456.587 | G10: =SUM(G8:G9) -> 54054.25
A11: Taxes | C11: =-IF(C10>0,C10*21%,0) -> -7233.366 | D11: =-IF(D10>0,D10*21%,0) -> -7439.6238 | E11: =-IF(E10>0,E10*21%,0) -> -9323.0287 | F11: =-IF(F10>0,F10*21%,0) -> -10805.883 | G11: =-IF(G10>0,G10*21%,0) -> -11351.392
A12: Net Income | C12: =SUM(C10:C11) -> 27211.234 | D12: =SUM(D10:D11) -> 27987.156 | E12: =SUM(E10:E11) -> 35072.346 | F12: =SUM(F10:F11) -> 40650.704 | G12: =SUM(G10:G11) -> 42702.857

Sheet balance sheet
A1: Balance Sheet
A2: Figures in USD | B2: 2023 | C2: =B2+1 -> 2024 | D2: =C2+1 -> 2025 | E2: =D2+1 -> 2026 | F2: =E2+1 -> 2027 | G2: =F2+1 -> 2028
A3: Cash & Cash Equivalents | B3: 14589 | C3: ='cashflow statement'!C20 -> 21534.405 | D3: ='cashflow statement'!D20 -> 32358.52 | E3: ='cashflow statement'!E20 -> 50080.897 | F3: ='cashflow statement'!F20 -> 71830.972 | G3: ='cashflow statement'!G20 -> 91753.805
A4: Accounts Receivable | B4: 9877 | C4: =Assumptions!D14*Assumptions!D18 -> 12323.498 | D4: =Assumptions!E14*Assumptions!E18 -> 12939.673 | E4: =Assumptions!F14*Assumptions!F18 -> 13863.936 | F4: =Assumptions!G14*Assumptions!G18 -> 14634.154 | G4: =Assumptions!H14*Assumptions!H18 -> 15404.373
A5: Inventory | B5: 8579 | C5: =Assumptions!D19*Assumptions!D15 -> 9643.2667 | D5: =Assumptions!E19*Assumptions!E15 -> 10125.43 | E5: =Assumptions!F19*Assumptions!F15 -> 10091.791 | F5: =Assumptions!G19*Assumptions!G15 -> 10119.824 | G5: =Assumptions!H19*Assumptions!H15 -> 10652.446
A6: Total Current Assets | B6: =SUM(B3:B5) -> 33045 | C6: =SUM(C3:C5) -> 43501.17 | D6: =SUM(D3:D5) -> 55423.623 | E6: =SUM(E3:E5) -> 74036.623 | F6: =SUM(F3:F5) -> 96584.949 | G6: =SUM(G3:G5) -> 117810.62
A7: Property Plant & Equipment (PPE) | B7: 48990 | C7: =Assumptions!D48 -> 57591 | D7: =Assumptions!E48 -> 61992 | E7: =Assumptions!F48 -> 63393 | F7: =Assumptions!G48 -> 61544 | G7: =Assumptions!H48 -> 58945
A8: Total Assets | B8: =SUM(B6:B7) -> 82035 | C8: =SUM(C6:C7) -> 101092.17 | D8: =SUM(D6:D7) -> 117415.62 | E8: =SUM(E6:E7) -> 137429.62 | F8: =SUM(F6:F7) -> 158128.95 | G8: =SUM(G6:G7) -> 176755.62
A10: Accounts Payable | B10: 14880 | C10: =Assumptions!D15*Assumptions!D20 -> 16725.936 | D10: =Assumptions!E15*Assumptions!E20 -> 17562.233 | E10: =Assumptions!F15*Assumptions!F20 -> 17503.887 | F10: =Assumptions!G15*Assumptions!G20 -> 17552.509 | G10: =Assumptions!H15*Assumptions!H20 -> 18476.325
A11: Revolver | B11: 0 | C11: =revolver!C13 -> 0 | D11: =revolver!D13 -> 0 | E11: =revolver!E13 -> 0 | F11: =revolver!F13 -> 0 | G11: =revolver!G13 -> 0
A12: Total Current Liabilities | B12: =SUM(B10:B11) -> 14880 | C12: =SUM(C10:C11) -> 16725.936 | D12: =SUM(D10:D11) -> 17562.233 | E12: =SUM(E10:E11) -> 17503.887 | F12: =SUM(F10:F11) -> 17552.509 | G12: =SUM(G10:G11) -> 18476.325
A14: Long Term Debt | B14: 40000 | C14: 40000 | D14: 40000 | E14: 40000 | F14: 40000 | G14: 40000
A15: Total Liabilities | B15: =SUM(B12,B14) -> 54880 | C15: =SUM(C12,C14) -> 56725.936 | D15: =SUM(D12,D14) -> 57562.233 | E15: =SUM(E12,E14) -> 57503.887 | F15: =SUM(F12,F14) -> 57552.509 | G15: =SUM(G12,G14) -> 58476.325
A17: Common Stock | B17: 25000 | C17: 25000 | D17: 25000 | E17: 25000 | F17: 25000 | G17: 25000
A18: Retained Earnings | B18: =24155-22000 -> 2155 | C18: =Assumptions!D54 -> 19366.234 | D18: =Assumptions!E54 -> 34853.39 | E18: =Assumptions!F54 -> 54925.736 | F18: =Assumptions!G54 -> 75576.441 | G18: =Assumptions!H54 -> 93279.298
A19: Total Shareholders' Equity | B19: =SUM(B17:B18) -> 27155 | C19: =SUM(C17:C18) -> 44366.234 | D19: =SUM(D17:D18) -> 59853.39 | E19: =SUM(E17:E18) -> 79925.736 | F19: =SUM(F17:F18) -> 100576.44 | G19: =SUM(G17:G18) -> 118279.3
A21: Total Liabilities & Equity | B21: =SUM(B15,B19) -> 82035 | C21: =SUM(C15,C19) -> 101092.17 | D21: =SUM(D15,D19) -> 117415.62 | E21: =SUM(E15,E19) -> 137429.62 | F21: =SUM(F15,F19) -> 158128.95 | G21: =SUM(G15,G19) -> 176755.62
A23: Balance Sheet Check | B23: =B21-B8 -> 0 | C23: =C21-C8 -> 0 | D23: =D21-D8 -> 0 | E23: =E21-E8 -> 0 | F23: =F21-F8 -> 0 | G23: =G21-G8 -> 0

Sheet cashflow statement
A1: Cash Flow Statement
A2: Net Income | C2: ='Income statement'!C12 -> 27211.234 | D2: ='Income statement'!D12 -> 27987.156 | E2: ='Income statement'!E12 -> 35072.346 | F2: ='Income statement'!F12 -> 40650.704 | G2: ='Income statement'!G12 -> 42702.857
A3: Depreciation | C3: =-'Income statement'!C7 -> 6399 | D3: =-'Income statement'!D7 -> 7599 | E3: =-'Income statement'!E7 -> 8599 | F3: =-'Income statement'!F7 -> 9349 | G3: =-'Income statement'!G7 -> 10099
A4: Change in Accounts Receivable | C4: =('balance sheet'!B4-'balance sheet'!C4) -> -2446.4983 | D4: =('balance sheet'!C4-'balance sheet'!D4) -> -616.17492 | E4: =('balance sheet'!D4-'balance sheet'!E4) -> -924.26237 | F4: =('balance sheet'!E4-'balance sheet'!F4) -> -770.21864 | G4: =('balance sheet'!F4-'balance sheet'!G4) -> -770.21864
A5: Change in Inventory | C5: ='balance sheet'!B5-'balance sheet'!C5 -> -1064.2667 | D5: ='balance sheet'!C5-'balance sheet'!D5 -> -482.16334 | E5: ='balance sheet'!D5-'balance sheet'!E5 -> 33.639303 | F5: ='balance sheet'!E5-'balance sheet'!F5 -> -28.032752 | G5: ='balance sheet'!F5-'balance sheet'!G5 -> -532.62229
A6: Change in Accounts Payable | C6: ='balance sheet'!C10-'balance sheet'!B10 -> 1845.9365 | D6: ='balance sheet'!D10-'balance sheet'!C10 -> 836.29682 | E6: ='balance sheet'!E10-'balance sheet'!D10 -> -58.34629 | F6: ='balance sheet'!F10-'balance sheet'!E10 -> 48.621908 | G6: ='balance sheet'!G10-'balance sheet'!F10 -> 923.81626
A7: Cash Flow from Operating Activities | C7: =SUM(C2:C6) -> 31945.405 | D7: =SUM(D2:D6) -> 35324.115 | E7: =SUM(E2:E6) -> 42722.377 | F7: =SUM(F2:F6) -> 49250.075 | G7: =SUM(G2:G6) -> 52422.833
A9: Capital Expenditures | C9: =Assumptions!C35 -> 15000 | D9: =Assumptions!C36 -> 12000 | E9: =Assumptions!C37 -> 10000 | F9: =Assumptions!C38 -> 7500 | G9: =Assumptions!C39 -> 7500
A10: Cash Flow from Investing Activities | C10: =-C9 -> -15000 | D10: =-D9 -> -12000 | E10: =-E9 -> -10000 | F10: =-F9 -> -7500 | G10: =-G9 -> -7500
A12: Change in LT Debt | C12: ='balance sheet'!C14-'balance sheet'!B14 -> 0 | D12: ='balance sheet'!D14-'balance sheet'!C14 -> 0 | E12: ='balance sheet'!E14-'balance sheet'!D14 -> 0 | F12: ='balance sheet'!F14-'balance sheet'!E14 -> 0 | G12: ='balance sheet'!G14-'balance sheet'!F14 -> 0
A13: Change in Revolver | C13: ='balance sheet'!C11-'balance sheet'!B11 -> 0 | D13: ='balance sheet'!C11 -> 0 | E13: ='balance sheet'!D11 -> 0 | F13: ='balance sheet'!E11 -> 0 | G13: ='balance sheet'!F11 -> 0
A14: Change in Common Stock | C14: ='balance sheet'!C17-'balance sheet'!B17 -> 0 | D14: ='balance sheet'!D17-'balance sheet'!C17 -> 0 | E14: ='balance sheet'!E17-'balance sheet'!D17 -> 0 | F14: ='balance sheet'!F17-'balance sheet'!E17 -> 0 | G14: ='balance sheet'!G17-'balance sheet'!F17 -> 0
A15: Dividends | C15: =Assumptions!D53 -> -10000 | D15: =Assumptions!E53 -> -12500 | E15: =Assumptions!F53 -> -15000 | F15: =Assumptions!G53 -> -20000 | G15: =Assumptions!H53 -> -25000
A16: Cash Flow from Financing Activities | C16: =SUM(C12:C15) -> -10000 | D16: =SUM(D12:D15) -> -12500 | E16: =SUM(E12:E15) -> -15000 | F16: =SUM(F12:F15) -> -20000 | G16: =SUM(G12:G15) -> -25000
A18: Beginning of Year Cash Balance | C18: ='balance sheet'!B3 -> 14589 | D18: ='balance sheet'!C3 -> 21534.405 | E18: ='balance sheet'!D3 -> 32358.52 | F18: ='balance sheet'!E3 -> 50080.897 | G18: ='balance sheet'!F3 -> 71830.972
A19: Change in Cash | C19: =SUM(C7,C10,C16) -> 6945.4054 | D19: =D7+D10+D16 -> 10824.115 | E19: =E7+E10+E16 -> 17722.377 | F19: =F7+F10+F16 -> 21750.075 | G19: =G7+G10+G16 -> 19922.833
A20: End of Year Cash Balance | C20: =SUM(C18:C19) -> 21534.405 | D20: =SUM(D18:D19) -> 32358.52 | E20: =SUM(E18:E19) -> 50080.897 | F20: =SUM(F18:F19) -> 71830.972 | G20: =SUM(G18:G19) -> 91753.805

Sheet revolver
A1: Revolver
A2: Available Cash
A3: Beginning Cash Balance | C3: ='balance sheet'!B3 -> 14589 | D3: ='balance sheet'!C3 -> 21534.405 | E3: ='balance sheet'!D3 -> 32358.52 | F3: ='balance sheet'!E3 -> 50080.897 | G3: ='balance sheet'!F3 -> 71830.972
A4: Cash from operations | C4: ='cashflow statement'!C7 -> 31945.405 | D4: ='cashflow statement'!D7 -> 35324.115 | E4: ='cashflow statement'!E7 -> 42722.377 | F4: ='cashflow statement'!F7 -> 49250.075 | G4: ='cashflow statement'!G7 -> 52422.833
A5: Cash from Investing | C5: ='cashflow statement'!C10 -> -15000 | D5: ='cashflow statement'!D10 -> -12000 | E5: ='cashflow statement'!E10 -> -10000 | F5: ='cashflow statement'!F10 -> -7500 | G5: ='cashflow statement'!G10 -> -7500
A6: Change in LT Debt | C6: ='cashflow statement'!C12 -> 0 | D6: ='cashflow statement'!D12 -> 0 | E6: ='cashflow statement'!E12 -> 0 | F6: ='cashflow statement'!F12 -> 0 | G6: ='cashflow statement'!G12 -> 0
A7: Change in Common Stock | C7: ='cashflow statement'!C14 -> 0 | D7: ='cashflow statement'!D14 -> 0 | E7: ='cashflow statement'!E14 -> 0 | F7: ='cashflow statement'!F14 -> 0 | G7: ='cashflow statement'!G14 -> 0
A8: Dividends | C8: ='cashflow statement'!C15 -> -10000 | D8: ='cashflow statement'!D15 -> -12500 | E8: ='cashflow statement'!E15 -> -15000 | F8: ='cashflow statement'!F15 -> -20000 | G8: ='cashflow statement'!G15 -> -25000
A9: Cash Available for Revolver | C9: =SUM(C3:C8) -> 21534.405 | D9: =SUM(D3:D8) -> 32358.52 | E9: =SUM(E3:E8) -> 50080.897 | F9: =SUM(F3:F8) -> 71830.972 | G9: =SUM(G3:G8) -> 91753.805
A11: Revolver
A12: Beginning Balance | C12: ='balance sheet'!B11 -> 0 | D12: ='balance sheet'!C11 -> 0 | E12: ='balance sheet'!D11 -> 0 | F12: ='balance sheet'!E11 -> 0 | G12: ='balance sheet'!F11 -> 0
A13: Change in Revolver | C13: =-MIN(C9,C12) -> 0 | D13: =-MIN(D9,D12) -> 0 | E13: =-MIN(E9,E12) -> 0 | F13: =-MIN(F9,F12) -> 0 | G13: =-MIN(G9,G12) -> 0
A14: Ending Balance | C14: =SUM(C12:C13) -> 0 | D14: =SUM(D12:D13) -> 0 | E14: =SUM(E12:E13) -> 0 | F14: =SUM(F12:F13) -> 0 | G14: =SUM(G12:G13) -> 0
A16: Revolver Interest Rate | C16: 0.05 | D16: 0.05 | E16: 0.05 | F16: 0.05 | G16: 0.05
A17: Interest Expense | C17: =C16*C14 -> 0 | D17: =D16*D14 -> 0 | E17: =E16*E14 -> 0 | F17: =F16*F14 -> 0 | G17: =G16*G14 -> 0
A18: Total Interest Expense | C18: =C16*C17+Assumptions!D24 -> 2800 | D18: =D16*D17+Assumptions!E24 -> 2800 | E18: =E16*E17+Assumptions!F24 -> 2800 | F18: =F16*F17+Assumptions!G24 -> 2800 | G18: =G16*G17+Assumptions!H24 -> 2800
